<?xml version="1.0" ?>
<!-- =================================================================================== -->
<!-- |    This document was autogenerated by xacro from xacro/main.xacro               | -->
<!-- |    EDITING THIS FILE BY HAND IS NOT RECOMMENDED                                 | -->
<!-- =================================================================================== -->
<robot name="robot" xmlns:xacro="http://ros.org/wiki/xacro">

  <link name="base_footprint"/>

  <link name="base_link">

    <inertial>
      <origin rpy="0 0 0" xyz="-5.0444E-05 9.8899E-18 0.017107"/>
      <mass value="0.27407"/>
      <inertia ixx="0.00068152" ixy="-7.0425E-23" ixz="-3.0993E-22" iyy="0.00067974" iyz="1.1361E-19" izz="0.001077"/>
    </inertial>

    <visual>
      <origin rpy="0 0 0" xyz="0 0 0"/>
      <geometry>
        <mesh filename="package://diffbot/meshes/visual/base_link.STL"/>
      </geometry>
      <material name="">
        <color rgba="0.1098 0.1098 0.1098 1"/>
      </material>
    </visual>

    <collision>
      <origin rpy="0 0 0" xyz="0 0 0"/>
      <geometry>
        <mesh filename="package://diffbot/meshes/collision/base_link.STL"/>
      </geometry>
    </collision>

  </link>

  <!-- Back caster link -->
  <link name="BackCasterLink">
    <inertial>
      <origin rpy="0 0 0" xyz="1.3878E-17 -1.2874E-35 0.017513"/>
      <mass value="0.015897"/>
      <inertia ixx="3.8221E-06" ixy="2.1372E-39" ixz="-2.2251E-23" iyy="3.8221E-06" iyz="4.0851E-39" izz="7.7388E-07"/>
    </inertial>

    <visual>
      <origin rpy="0 0 0" xyz="0 0 0"/>
      <geometry>
        <mesh filename="package://diffbot/meshes/visual/BackCasterLink.STL"/>
      </geometry>
      <material name="">
        <color rgba="0.79216 0.81961 0.93333 1"/>
      </material>
    </visual>

    <collision>
      <origin rpy="0 0 0" xyz="0 0 0"/>
      <geometry>
        <mesh filename="package://diffbot/meshes/collision/BackCasterLink.STL"/>
      </geometry>
    </collision>

  </link>

  <!-- Back caster joint -->
  <joint name="back_caster_joint" type="fixed">
    <origin rpy="0 0 0" xyz="-0.09 0 -0.042868"/>
    <parent link="base_link"/>
    <child link="BackCasterLink"/>
  </joint>

  <!-- Right wheel link -->
  <link name="RightWheelLink">

    <inertial>
      <origin rpy="0 0 0" xyz="3.1542E-10 -1.863E-08 -0.007373"/>
      <mass value="0.16695"/>
      <inertia ixx="6.7293E-05" ixy="1.9509E-10" ixz="-5.1237E-14" iyy="6.7296E-05" iyz="3.2071E-12" izz="0.00011321"/>
    </inertial>

    <visual>
      <origin rpy="0 0 0" xyz="0 0 0"/>
      <geometry>
        <mesh filename="package://diffbot/meshes/visual/RightWheelLink.STL"/>
      </geometry>
      <material name="">
        <color rgba="0.79216 0.81961 0.93333 1"/>
      </material>
    </visual>

    <collision>
      <origin rpy="0 0 0" xyz="0 0 0"/>
      <geometry>
        <mesh filename="package://diffbot/meshes/collision/RightWheelLink.STL"/>
      </geometry>
    </collision>

  </link>

  <!-- Right wheel joint -->
  <joint name="right_wheel_joint" type="revolute">
    <origin rpy="1.5708 0 0" xyz="0 -0.1255 -0.02"/>
    <parent link="base_link"/>
    <child link="RightWheelLink"/>
    <axis xyz="0 0 -1"/>
    <limit effort="10" lower="-3.14" upper="3.14" velocity="10"/>
    <dynamics damping="1" friction="1"/>
  </joint>

  <!-- Front caster link -->
  <link name="FrontCasterLink">

    <inertial>
      <origin rpy="0 0 0" xyz="1.3878E-17 -1.2874E-35 0.017513"/>
      <mass value="0.015897"/>
      <inertia ixx="3.8221E-06" ixy="2.1372E-39" ixz="-2.2251E-23" iyy="3.8221E-06" iyz="4.0851E-39" izz="7.7388E-07"/>
    </inertial>

    <visual>
      <origin rpy="0 0 0" xyz="0 0 0"/>
      <geometry>
        <mesh filename="package://diffbot/meshes/visual/FrontCasterLink.STL"/>
      </geometry>
      <material name="">
        <color rgba="0.79216 0.81961 0.93333 1"/>
      </material>
    </visual>

    <collision>
      <origin rpy="0 0 0" xyz="0 0 0"/>
      <geometry>
        <mesh filename="package://diffbot/meshes/collision/FrontCasterLink.STL"/>
      </geometry>
    </collision>

  </link>

  <!-- Front caster joint -->
  <joint name="front_caster_joint" type="fixed">
    <origin rpy="0 0 0" xyz="0.09 0 -0.042868"/>
    <parent link="base_link"/>
    <child link="FrontCasterLink"/>
  </joint>

  <!-- Lidar link -->
  <link name="LidarLink">
    
    <inertial>
      <origin rpy="0 0 0" xyz="2.0536E-18 -1.491E-20 0.02"/>
      <mass value="0.025133"/>
      <inertia ixx="3.351E-06" ixy="2.2279E-22" ixz="-3.5293E-23" iyy="3.351E-06" iyz="-1.1516E-37" izz="5.0265E-06"/>
    </inertial>

    <visual>
      <origin rpy="0 0 0" xyz="0 0 0"/>
      <geometry>
        <mesh filename="package://diffbot/meshes/visual/LidarLink.STL"/>
      </geometry>
      <material name="">
        <color rgba="0.79216 0.81961 0.93333 1"/>
      </material>
    </visual>

    <collision>
      <origin rpy="0 0 0" xyz="0 0 0"/>
      <geometry>
        <mesh filename="package://diffbot/meshes/collision/LidarLink.STL"/>
      </geometry>
    </collision>

  </link>

  <!-- Lidar joint -->
  <joint name="lidar_joint" type="fixed">
    <origin rpy="0 0 0" xyz="0 0 0.056"/>
    <parent link="base_link"/>
    <child link="LidarLink"/>
    <axis xyz="0 0 0"/>
  </joint>

  <!-- Left wheel link -->
  <link name="LeftWheelLink">
    <inertial>
      <origin rpy="0 0 0" xyz="7.333E-09 -1.7129E-08 0.007373"/>
      <mass value="0.16695"/>
      <inertia ixx="6.7293E-05" ixy="-1.516E-09" ixz="1.2651E-12" iyy="6.7296E-05" iyz="-2.9475E-12" izz="0.00011321"/>
    </inertial>
    <visual>
      <origin rpy="0 0 0" xyz="0 0 0"/>
      <geometry>
        <mesh filename="package://diffbot/meshes/visual/LeftWheelLink.STL"/>
      </geometry>
      <material name="">
        <color rgba="0.79216 0.81961 0.93333 1"/>
      </material>
    </visual>
    <collision>
      <origin rpy="0 0 0" xyz="0 0 0"/>
      <geometry>
        <mesh filename="package://diffbot/meshes/collision/LeftWheelLink.STL"/>
      </geometry>
    </collision>
  </link>
  <!-- left_wheel_joint -->
  <joint name="left_wheel_joint" type="revolute">
    <origin rpy="1.5708 0 0" xyz="0 0.1255 -0.02"/>
    <parent link="base_link"/>
    <child link="LeftWheelLink"/>
    <axis xyz="0 0 1"/>
    <limit effort="10" lower="-3.14" upper="3.14" velocity="10"/>
    <dynamics damping="1" friction="1"/>
  </joint>

  <!-- ros2_control -->
  <ros2_control name="DiffBotSystem" type="system">
    <hardware>
      <plugin>gz_ros2_control/GazeboSystem</plugin>
    </hardware>
    <joint name="left_wheel_joint">
      <command_interface name="velocity">
        <param name="min">-2</param>
        <param name="max">2</param>
      </command_interface>
      <state_interface name="velocity"/>
      <state_interface name="position"/>
    </joint>
    <joint name="right_wheel_joint">
      <command_interface name="velocity">
        <param name="min">-2</param>
        <param name="max">2</param>
      </command_interface>
      <state_interface name="velocity"/>
      <state_interface name="position"/>
    </joint>
  </ros2_control>
  <gazebo>
    <!-- Joint state publisher -->
    <plugin filename="libgz_ros2_control.so" name="gz_ros2_control::GazeboSimROS2ControlPlugin">
      <robot_param>robot_description</robot_param>
      <robot_param_node>robot_state_publisher</robot_param_node>
      <parameters>/home/pontus/ros2_ws/install/diffbot/share/diffbot/config/ros2_controller.yaml</parameters>
    </plugin>
  </gazebo>
  <material name="whites">
    <color rgba="1 1 1 1"/>
  </material>
  <!-- IMU Sensor -->
  <link name="imu_link">
    <inertial>
      <mass value="0.01"/>
      <origin rpy="0 0 0" xyz="0 0 0"/>
      <inertia ixx="1e-5" ixy="0" ixz="0" iyy="1e-5" iyz="0" izz="1e-5"/>
    </inertial>
    <visual>
      <origin xyz="0 0 0.045"/>
      <geometry>
        <box size="0.02 0.02 0.02"/>
      </geometry>
      <material name="whites"/>
    </visual>
    <collision>
      <origin xyz="0 0 0.045"/>
      <geometry>
        <box size="0.02 0.02 0.02"/>
      </geometry>
    </collision>
  </link>
  <joint name="imu_joint" type="fixed">
    <parent link="base_link"/>
    <child link="imu_link"/>
    <origin rpy="0 0 0" xyz="0 0 0.045"/>
  </joint>
  <gazebo reference="imu_link">
    <gravity>true</gravity>
    <sensor name="imu_sensor" type="imu">
      <always_on>true</always_on>
      <update_rate>100</update_rate>
      <visualize>true</visualize>
      <topic>__default_topic__</topic>
      <plugin filename="libgazebo_ros_imu_sensor.so" name="imu">
        <ros>
          <namespace>/</namespace>
          <remapping>imu/out:=imu</remapping>
        </ros>
        <topicName>/imu</topicName>
        <bodyName>imu_link</bodyName>
        <updateRateHZ>10.0</updateRateHZ>
        <gaussianNoise>0.0</gaussianNoise>
        <xyzOffset>0 0 0</xyzOffset>
        <rpyOffset>0 0 0</rpyOffset>
        <frameName>imu_link</frameName>
        <initialOrientationAsReference>false</initialOrientationAsReference>
      </plugin>
      <pose>0 0 0 0 0 0</pose>
    </sensor>
  </gazebo>
  <!-- Specify some standard inertial calculations https://en.wikipedia.org/wiki/List_of_moments_of_inertia -->
  <!-- These make use of xacro's mathematical functionality -->
  <joint name="laser_joint" type="fixed">
    <parent link="base_link"/>
    <child link="laser_frame"/>
    <origin rpy="0 0 0" xyz="0 0 0.110"/>
  </joint>
  <link name="laser_frame">
    <visual>
      <geometry>
        <cylinder length="0.05" radius="0.035"/>
      </geometry>
    </visual>
    <collision>
      <geometry>
        <cylinder length="0.05" radius="0.035"/>
      </geometry>
    </collision>
    <inertial>
      <origin rpy="0 0 0" xyz="0 0 0"/>
      <mass value="0.1"/>
      <inertia ixx="5.145833333333335e-05" ixy="0.0" ixz="0.0" iyy="5.145833333333335e-05" iyz="0.0" izz="6.125000000000001e-05"/>
    </inertial>
  </link>
  <gazebo reference="laser_frame">
    <material>Gazebo/Red</material>
    <sensor name="laser" type="gpu_lidar">
      <always_on>true</always_on>
      <pose> 0 0 0 0 0 0 </pose>
      <visualize> true </visualize>
      <update_rate>10</update_rate>
      <lidar>
        <scan>
          <horizontal>
            <samples>360</samples>
            <resolution>1</resolution>
            <min_angle>-3.14</min_angle>
            <max_angle>3.14</max_angle>
          </horizontal>
        </scan>
        <range>
          <min>0.3</min>
          <max>12</max>
          <resolution>0.01</resolution>
        </range>
      </lidar>
      <plugin filename="libgazebo_ros_ray_sensor.so" name="laser_controller">
        <ros>
          <namespace>/</namespace>
          <remapping>laser_controller/out:=scan</remapping>
        </ros>
        <output_type>sensor_msgs/LaserScan</output_type>
        <frame_name>laser_frame</frame_name>
      </plugin>
    </sensor>
  </gazebo>
</robot>
