<robot name="diffbot">

  <link name="base_link">
    <inertial>
      <origin xyz="-5.0444E-05 9.8899E-18 0.017107" rpy="0 0 0" />
      <mass value="0.27407" />
      <inertia ixx="0.00068152" ixy="-7.0425E-23" ixz="-3.0993E-22" iyy="0.00067974" iyz="1.1361E-19" izz="0.001077" />
    </inertial>
    <visual>
      <origin xyz="0 0 0" rpy="0 0 0" />
      <geometry>
        <mesh filename="package://diffbot/meshes/visual/base_link.STL" />
      </geometry>
      <material name="">
        <color rgba="0.1098 0.1098 0.1098 1" />
      </material>
    </visual>
    <collision>
      <origin xyz="0 0 0" rpy="0 0 0" />
      <geometry>
        <mesh filename="package://diffbot/meshes/collision/base_link.STL" />
      </geometry>
    </collision>
  </link>
  <link name="BackCasterLink">
    <inertial>
      <origin xyz="1.3878E-17 -1.2874E-35 0.017513" rpy="0 0 0" />
      <mass value="0.015897" />
      <inertia ixx="3.8221E-06" ixy="2.1372E-39" ixz="-2.2251E-23" iyy="3.8221E-06" iyz="4.0851E-39" izz="7.7388E-07" />
    </inertial>
    <visual>
      <origin xyz="0 0 0" rpy="0 0 0" />
      <geometry>
        <mesh filename="package://diffbot/meshes/visual/BackCasterLink.STL" />
      </geometry>
      <material name="">
        <color rgba="0.79216 0.81961 0.93333 1" />
      </material>
    </visual>
    <collision>
      <origin xyz="0 0 0" rpy="0 0 0" />
      <geometry>
        <mesh filename="package://diffbot/meshes/collision/BackCasterLink.STL" />
      </geometry>
    </collision>
  </link>
  <joint name="back_caster_joint" type="continuous">
    <origin xyz="-0.09 0 -0.042868" rpy="0 0 0" />
    <parent link="base_link" />
    <child link="BackCasterLink" />
    <axis xyz="0 0 -1" />
    <limit lower="-3.14" upper="3.14" effort="10" velocity="10" />
    <dynamics damping="0.0001" friction="0.0001" />
  </joint>
  <link name="RightWheelLink">
    <inertial>
      <origin xyz="3.1542E-10 -1.863E-08 -0.007373" rpy="0 0 0" />
      <mass value="0.16695" />
      <inertia ixx="6.7293E-05" ixy="1.9509E-10" ixz="-5.1237E-14" iyy="6.7296E-05" iyz="3.2071E-12" izz="0.00011321" />
    </inertial>
    <visual>
      <origin xyz="0 0 0" rpy="0 0 0" />
      <geometry>
        <mesh filename="package://diffbot/meshes/visual/RightWheelLink.STL" />
      </geometry>
      <material name="">
        <color rgba="0.79216 0.81961 0.93333 1" />
      </material>
    </visual>
    <collision>
      <origin xyz="0 0 0" rpy="0 0 0" />
      <geometry>
        <mesh filename="package://diffbot/meshes/collision/RightWheelLink.STL" />
      </geometry>
    </collision>
  </link>
  <joint name="right_wheel_joint" type="revolute">
    <origin xyz="0 -0.1255 -0.02" rpy="1.5708 0 0" />
    <parent link="base_link" />
    <child link="RightWheelLink" />
    <axis xyz="0 0 -1" />
    <limit lower="-3.14" upper="3.14" effort="10" velocity="10" />
    <dynamics damping="1" friction="1" />
  </joint>
  <link name="FrontCasterLink">
    <inertial>
      <origin xyz="1.3878E-17 -1.2874E-35 0.017513" rpy="0 0 0" />
      <mass value="0.015897" />
      <inertia ixx="3.8221E-06" ixy="2.1372E-39" ixz="-2.2251E-23" iyy="3.8221E-06" iyz="4.0851E-39" izz="7.7388E-07" />
    </inertial>
    <visual>
      <origin xyz="0 0 0" rpy="0 0 0" />
      <geometry>
        <mesh filename="package://diffbot/meshes/visual/FrontCasterLink.STL" />
      </geometry>
      <material name="">
        <color rgba="0.79216 0.81961 0.93333 1" />
      </material>
    </visual>
    <collision>
      <origin xyz="0 0 0" rpy="0 0 0" />
      <geometry>
        <mesh filename="package://diffbot/meshes/collision/FrontCasterLink.STL" />
      </geometry>
    </collision>
  </link>
  <joint name="front_caster_joint" type="continuous">
    <origin xyz="0.09 0 -0.042868" rpy="0 0 0" />
    <parent link="base_link" />
    <child link="FrontCasterLink" />
    <axis xyz="0 0 -1" />
    <limit lower="-3.14" upper="3.14" effort="10" velocity="10" />
    <dynamics damping="0.0001" friction="0.0001" />
  </joint>
  <link name="LidarLink">
    <inertial>
      <origin xyz="2.0536E-18 -1.491E-20 0.02" rpy="0 0 0" />
      <mass value="0.025133" />
      <inertia ixx="3.351E-06" ixy="2.2279E-22" ixz="-3.5293E-23" iyy="3.351E-06" iyz="-1.1516E-37" izz="5.0265E-06" />
    </inertial>
    <visual>
      <origin xyz="0 0 0" rpy="0 0 0" />
      <geometry>
        <mesh filename="package://diffbot/meshes/visual/LidarLink.STL" />
      </geometry>
      <material name="">
        <color rgba="0.79216 0.81961 0.93333 1" />
      </material>
    </visual>
    <collision>
      <origin xyz="0 0 0" rpy="0 0 0" />
      <geometry>
        <mesh filename="package://diffbot/meshes/collision/LidarLink.STL" />
      </geometry>
    </collision>
  </link>
  <joint name="lidar_joint" type="fixed">
    <origin xyz="0 0 0.056" rpy="0 0 0" />
    <parent link="base_link" />
    <child link="LidarLink" />
    <axis xyz="0 0 0" />
  </joint>
  <link name="LeftWheelLink">
    <inertial>
      <origin xyz="7.333E-09 -1.7129E-08 0.007373" rpy="0 0 0" />
      <mass value="0.16695" />
      <inertia ixx="6.7293E-05" ixy="-1.516E-09" ixz="1.2651E-12" iyy="6.7296E-05" iyz="-2.9475E-12" izz="0.00011321" />
    </inertial>
    <visual>
      <origin xyz="0 0 0" rpy="0 0 0" />
      <geometry>
        <mesh filename="package://diffbot/meshes/visual/LeftWheelLink.STL" />
      </geometry>
      <material name="">
        <color rgba="0.79216 0.81961 0.93333 1" />
      </material>
    </visual>
    <collision>
      <origin xyz="0 0 0" rpy="0 0 0" />
      <geometry>
        <mesh filename="package://diffbot/meshes/collision/LeftWheelLink.STL" />
      </geometry>
    </collision>
  </link>
  <joint name="left_wheel_joint" type="revolute">
    <origin xyz="0 0.1255 -0.02" rpy="1.5708 0 0" />
    <parent link="base_link" />
    <child link="LeftWheelLink" />
    <axis xyz="0 0 1" />
    <limit lower="-3.14" upper="3.14" effort="10" velocity="10" />
    <dynamics damping="1" friction="1" />
  </joint>
</robot>