<?xml version="1.0" ?>
<!-- =================================================================================== -->
<!-- |    This document was autogenerated by xacro from robot.urdf.xacro               | -->
<!-- |    EDITING THIS FILE BY HAND IS NOT RECOMMENDED                                 | -->
<!-- =================================================================================== -->
<robot name="robot">
  <!-- Specify some standard inertial calculations https://en.wikipedia.org/wiki/List_of_moments_of_inertia -->
  <!-- These make use of xacro's mathematical functionality -->
  <material name="white">
    <color rgba="1 1 1 1"/>
  </material>
  <material name="orange">
    <color rgba="1 0.3 0.1 1"/>
  </material>
  <material name="blue">
    <color rgba="0.2 0.2 1 1"/>
  </material>
  <material name="black">
    <color rgba="0 0 0 1"/>
  </material>
  <material name="red">
    <color rgba="1 0 0 1"/>
  </material>
  <!-- BASE LINK -->
  <link name="base_link">

    </link>
  <joint name="base_footprint_joint" type="fixed">
    <parent link="base_link"/>
    <child link="base_footprint"/>
    <origin rpy="0 0 0" xyx="0 0 0"/>
  </joint>
  <link name="base_footprint">
    </link>
  <!-- CHASSIS LINK -->
  <joint name="chassis_joint" type="fixed">
    <parent link="base_link"/>
    <child link="chassis"/>
    <origin xyz="0 0 0"/>
  </joint>
  <link name="chassis">
    <visual>
      <origin xyz="0 0 0.065"/>
      <!-- half the height (90mm) is 45mm, plus 20mm above ground -->
      <geometry>
        <cylinder length="0.09" radius="0.1"/>
      </geometry>
      <material name="white"/>
    </visual>
    <collision>
      <origin xyz="0 0 0.065"/>
      <geometry>
        <cylinder length="0.09" radius="0.1"/>
      </geometry>
    </collision>
    <inertial>
      <origin rpy="0 0 0" xyz="0 0 0.065"/>
      <mass value="0.5"/>
      <inertia ixx="0.0015875000000000004" ixy="0.0" ixz="0.0" iyy="0.0015875000000000004" iyz="0.0" izz="0.0025000000000000005"/>
    </inertial>
  </link>
  <!-- <link name="chassis"> -->
  <!--     <visual> -->
  <!--         <origin xyz="0.15 0 0.075"/> -->
  <!--         <geometry> -->
  <!--             <box size="0.3 0.3 0.15"/> -->
  <!--         </geometry> -->
  <!--         <material name="white"/> -->
  <!--     </visual> -->
  <!--     <collision> -->
  <!--         <origin xyz="0.15 0 0.075"/> -->
  <!--         <geometry> -->
  <!--             <box size="0.3 0.3 0.15"/> -->
  <!--         </geometry> -->
  <!--     </collision> -->
  <!--     <xacro:inertial_box mass="0.5" x="0.3" y="0.3" z="0.15"> -->
  <!--         <origin xyz="0.15 0 0.075" rpy="0 0 0"/> -->
  <!--     </xacro:inertial_box> -->
  <!-- </link> -->
  <!---->
  <gazebo reference="chassis">
    <material>Gazebo/White</material>
  </gazebo>
  <!-- LEFT WHEEL LINK -->
  <joint name="left_wheel_joint" type="continuous">
    <parent link="base_link"/>
    <child link="left_wheel"/>
    <origin rpy="-1.5707963267948966 0 0" xyz="0 0.1175 0"/>
    <axis xyz="0 0 1"/>
  </joint>
  <link name="left_wheel">
    <visual>
      <geometry>
        <cylinder length="0.035" radius="0.035"/>
      </geometry>
      <material name="blue"/>
    </visual>
    <collision>
      <geometry>
        <sphere radius="0.035"/>
      </geometry>
    </collision>
    <inertial>
      <origin rpy="0 0 0" xyz="0 0 0"/>
      <mass value="0.1"/>
      <inertia ixx="4.083333333333334e-05" ixy="0.0" ixz="0.0" iyy="4.083333333333334e-05" iyz="0.0" izz="6.125000000000001e-05"/>
    </inertial>
  </link>
  <gazebo reference="left_wheel">
    <material>Gazebo/Blue</material>
  </gazebo>
  <!-- RIGHT WHEEL LINK -->
  <joint name="right_wheel_joint" type="continuous">
    <parent link="base_link"/>
    <child link="right_wheel"/>
    <origin rpy="1.5707963267948966 0 0" xyz="0 -0.1175 0"/>
    <axis xyz="0 0 -1"/>
  </joint>
  <link name="right_wheel">
    <visual>
      <geometry>
        <cylinder length="0.035" radius="0.035"/>
      </geometry>
      <material name="blue"/>
    </visual>
    <collision>
      <geometry>
        <sphere radius="0.035"/>
      </geometry>
    </collision>
    <inertial>
      <origin rpy="0 0 0" xyz="0 0 0"/>
      <mass value="0.1"/>
      <inertia ixx="4.083333333333334e-05" ixy="0.0" ixz="0.0" iyy="4.083333333333334e-05" iyz="0.0" izz="6.125000000000001e-05"/>
    </inertial>
  </link>
  <gazebo reference="right_wheel">
    <material>Gazebo/Blue</material>
  </gazebo>
  <!-- CASTER WHEEL LINK -->
  <joint name="caster_wheel_joint" type="fixed">
    <parent link="chassis"/>
    <child link="caster_wheel"/>
    <origin xyz="0.09 0 0"/>
  </joint>
  <link name="caster_wheel">
    <visual>
      <geometry>
        <sphere radius="0.035"/>
      </geometry>
      <material name="black"/>
    </visual>
    <collision>
      <geometry>
        <sphere radius="0.035"/>
      </geometry>
    </collision>
    <inertial>
      <origin rpy="0 0 0" xyz="0 0 0"/>
      <mass value="0.1"/>
      <inertia ixx="4.900000000000002e-05" ixy="0.0" ixz="0.0" iyy="4.900000000000002e-05" iyz="0.0" izz="4.900000000000002e-05"/>
    </inertial>
  </link>
  <joint name="caster_wheel_joint2" type="fixed">
    <parent link="chassis"/>
    <child link="caster_wheel2"/>
    <origin xyz="-0.09 0 0"/>
  </joint>
  <link name="caster_wheel2">
    <visual>
      <geometry>
        <sphere radius="0.035"/>
      </geometry>
      <material name="black"/>
    </visual>
    <collision>
      <geometry>
        <sphere radius="0.035"/>
      </geometry>
    </collision>
    <inertial>
      <origin rpy="0 0 0" xyz="0 0 0"/>
      <mass value="0.1"/>
      <inertia ixx="4.900000000000002e-05" ixy="0.0" ixz="0.0" iyy="4.900000000000002e-05" iyz="0.0" izz="4.900000000000002e-05"/>
    </inertial>
  </link>
  <gazebo reference="caster_wheel">
    <material>Gazebo/Black</material>
    <mu1 value="0.001"/>
    <mu2 value="0.001"/>
  </gazebo>
  <gazebo reference="caster_wheel2">
    <material>Gazebo/Black</material>
    <mu1 value="0.001"/>
    <mu2 value="0.001"/>
  </gazebo>
  <ros2_control name="DiffBotSystem" type="system">
    <hardware>
      <plugin>gz_ros2_control/GazeboSystem</plugin>
    </hardware>
    <joint name="left_wheel_joint">
      <command_interface name="velocity">
        <param name="min">-2</param>
        <param name="max">2</param>
      </command_interface>
      <state_interface name="velocity"/>
      <state_interface name="position"/>
    </joint>
    <joint name="right_wheel_joint">
      <command_interface name="velocity">
        <param name="min">-2</param>
        <param name="max">2</param>
      </command_interface>
      <state_interface name="velocity"/>
      <state_interface name="position"/>
    </joint>
  </ros2_control>
  <gazebo>
    <plugin filename="libgz_ros2_control.so" name="gz_ros2_control::GazeboSimROS2ControlPlugin">
      <robot_param>robot_description</robot_param>
      <robot_param_node>robot_state_publisher</robot_param_node>
      <parameters>/home/pontus/ros2_ws/install/diffbot/share/diffbot/config/ros2_controller.yaml</parameters>
      <parameters>/home/pontus/ros2_ws/install/diffbot/share/diffbot/config/gaz_ros2_ctl_use_sim.yaml</parameters>
    </plugin>
  </gazebo>
  <joint name="laser_joint" type="fixed">
    <parent link="chassis"/>
    <child link="laser_frame"/>
    <origin rpy="0 0 0" xyz="0 0 0.110"/>
  </joint>
  <link name="laser_frame">
    <visual>
      <geometry>
        <cylinder length="0.05" radius="0.035"/>
      </geometry>
      <material name="red"/>
    </visual>
    <collision>
      <geometry>
        <cylinder length="0.05" radius="0.035"/>
      </geometry>
    </collision>
    <inertial>
      <origin rpy="0 0 0" xyz="0 0 0"/>
      <mass value="0.1"/>
      <inertia ixx="5.145833333333335e-05" ixy="0.0" ixz="0.0" iyy="5.145833333333335e-05" iyz="0.0" izz="6.125000000000001e-05"/>
    </inertial>
  </link>
  <gazebo reference="laser_frame">
    <material>Gazebo/Red</material>
    <sensor name="laser" type="gpu_lidar">
      <always_on>true</always_on>
      <pose> 0 0 0 0 0 0 </pose>
      <visualize> true </visualize>
      <update_rate>10</update_rate>
      <lidar>
        <scan>
          <horizontal>
            <samples>360</samples>
            <resolution>1</resolution>
            <min_angle>-3.14</min_angle>
            <max_angle>3.14</max_angle>
          </horizontal>
        </scan>
        <range>
          <min>0.3</min>
          <max>12</max>
          <resolution>0.01</resolution>
        </range>
      </lidar>
      <plugin filename="libgazebo_ros_ray_sensor.so" name="laser_controller">
        <ros>
          <namespace>/</namespace>
          <remapping>laser_controller/out:=scan</remapping>
        </ros>
        <output_type>sensor_msgs/LaserScan</output_type>
        <frame_name>laser_frame</frame_name>
      </plugin>
    </sensor>
  </gazebo>
  <material name="whites">
    <color rgba="1 1 1 1"/>
  </material>
  <!-- IMU Sensor -->
  <link name="imu_link">
    <inertial>
      <mass value="0.01"/>
      <origin rpy="0 0 0" xyz="0 0 0"/>
      <inertia ixx="1e-5" ixy="0" ixz="0" iyy="1e-5" iyz="0" izz="1e-5"/>
    </inertial>
    <visual>
      <origin xyz="0 0 0.045"/>
      <geometry>
        <box size="0.02 0.02 0.02"/>
      </geometry>
      <material name="whites"/>
    </visual>
    <collision>
      <origin xyz="0 0 0.045"/>
      <geometry>
        <box size="0.02 0.02 0.02"/>
      </geometry>
    </collision>
  </link>
  <joint name="imu_joint" type="fixed">
    <parent link="base_link"/>
    <child link="imu_link"/>
    <origin rpy="0 0 0" xyz="0 0 0.045"/>
  </joint>
  <gazebo reference="imu_link">
    <gravity>true</gravity>
    <sensor name="imu_sensor" type="imu">
      <always_on>true</always_on>
      <update_rate>100</update_rate>
      <visualize>true</visualize>
      <topic>__default_topic__</topic>
      <plugin filename="libgazebo_ros_imu_sensor.so" name="imu">
        <ros>
          <namespace>/</namespace>
          <remapping>imu/out:=imu</remapping>
        </ros>
        <topicName>/imu</topicName>
        <bodyName>imu_link</bodyName>
        <updateRateHZ>10.0</updateRateHZ>
        <gaussianNoise>0.0</gaussianNoise>
        <xyzOffset>0 0 0</xyzOffset>
        <rpyOffset>0 0 0</rpyOffset>
        <frameName>imu_link</frameName>
        <initialOrientationAsReference>false</initialOrientationAsReference>
      </plugin>
      <pose>0 0 0 0 0 0</pose>
    </sensor>
  </gazebo>
</robot>
